Workbook

Sheet Glide_Path
A1: PORTFOLIO GLIDE PATH - 15 YEAR PROJECTION
A3: ASSUMPTIONS | C3: VALUE | F3: Dots | G3: X(Risk) | H3: Y(Return)
A4: Risk-Free Rate | C4: 0.0365 | F4: Risk-Free Point | G4: 0 | H4: 0.0365
A5: Avg Stock Expected Return | C5: 0.3903238 | F5: Optimal Portfolio | G5: 0.184 | H5: 0.282
A6: Avg Bond ETF Expected Return | C6: 0.030506116
A7: Avg Stock Volatility | C7: 0.2619218
A8: Avg Bond Volatility | C8: 0.0041305485
A9: Stock-Bond Correlation | C9: 0.15 | F9: =SQRT((B9^2)*($C$7^2) + (C9^2)*($C$8^2) + 2*B9*C9*$C$9*$C$7*$C$8) -> 0.00061958227 | H9: 0.18353523
E11: 0.28237849 | G11: 0.18353523
H12: 1.3396801
A13: Annual Contribution | C13: 10000
A15: ANNUAL ALLOCATION & PORTFOLIO METRICS
A16: Year | B16: Stock % | C16: Bond % | D16: Check | E16: Exp Return | F16: Volatility | G16: Sharpe | H16: Base Value | I16: Conservative | J16: Optimistic | M16: Portfolio Value Over time
A17: 1 | B17: 0.7 | C17: 0.3 | D17: =B17+C17 -> 1 | E17: =B17*$C$5+C17*$C$6 -> 0.28237849 | F17: =SQRT((B17^2)*($C$7^2) + (C17^2)*($C$8^2) + 2*B17*C17*$C$9*$C$7*$C$8) -> 0.18353523 | G17: =(E17-$C$4)/F17 -> 1.3396801 | H17: =$C$13*(1+E17) -> 12823.785 | I17: =$C$13*(1+E17-F17) -> 10988.433 | J17: =$C$13*(1+E17+F17) -> 14659.137
A18: 2 | B18: 0.6786 | C18: 0.3214 | D18: =B18+C18 -> 1 | E18: =B18*$C$5+C18*$C$6 -> 0.2746784 | F18: =SQRT((B18^2)*($C$7^2) + (C18^2)*($C$8^2) + 2*B18*C18*$C$9*$C$7*$C$8) -> 0.17794411 | G18: =(E18-$C$4)/F18 -> 1.3385011 | H18: =(H17+$C$13)*(1+E18) -> 29092.986 | I18: =(I17+$C$13)*(1+E18-F18) -> 23018.734 | J18: =(J17+$C$13)*(1+E18+F18) -> 35820.418
A19: 3 | B19: 0.6571 | C19: 0.3429 | D19: =B19+C19 -> 1 | E19: =B19*$C$5+C19*$C$6 -> 0.26694232 | F19: =SQRT((B19^2)*($C$7^2) + (C19^2)*($C$8^2) + 2*B19*C19*$C$9*$C$7*$C$8) -> 0.17232696 | G19: =(E19-$C$4)/F19 -> 1.3372389 | H19: =(H18+$C$13)*(1+E19) -> 49528.558 | I19: =(I18+$C$13)*(1+E19-F19) -> 36142.813 | J19: =(J18+$C$13)*(1+E19+F19) -> 65947.919
A20: 4 | B20: 0.6357 | C20: 0.3643 | D20: =B20+C20 -> 1 | E20: =B20*$C$5+C20*$C$6 -> 0.25924222 | F20: =SQRT((B20^2)*($C$7^2) + (C20^2)*($C$8^2) + 2*B20*C20*$C$9*$C$7*$C$8) -> 0.16673604 | G20: =(E20-$C$4)/F20 -> 1.3358972 | H20: =(H19+$C$13)*(1+E20) -> 74960.873 | I20: =(I19+$C$13)*(1+E20-F20) -> 50411.308 | J20: =(J19+$C$13)*(1+E20+F20) -> 108300.08
A21: 5 | B21: 0.6143 | C21: 0.3857 | D21: =B21+C21 -> 1 | E21: =B21*$C$5+C21*$C$6 -> 0.25154212 | F21: =SQRT((B21^2)*($C$7^2) + (C21^2)*($C$8^2) + 2*B21*C21*$C$9*$C$7*$C$8) -> 0.16114524 | G21: =(E21-$C$4)/F21 -> 1.3344615 | H21: =(H20+$C$13)*(1+E21) -> 106332.11 | I21: =(I20+$C$13)*(1+E21-F21) -> 65872.302 | J21: =(J20+$C$13)*(1+E21+F21) -> 167121.03
A22: 6 | B22: 0.5929 | C22: 0.4071 | D22: =B22+C22 -> 1 | E22: =B22*$C$5+C22*$C$6 -> 0.24384202 | F22: =SQRT((B22^2)*($C$7^2) + (C22^2)*($C$8^2) + 2*B22*C22*$C$9*$C$7*$C$8) -> 0.15555455 | G22: =(E22-$C$4)/F22 -> 1.3329216 | H22: =(H21+$C$13)*(1+E22) -> 144698.77 | I22: =(I21+$C$13)*(1+E22-F22) -> 82570.875 | J22: =(J21+$C$13)*(1+E22+F22) -> 247862.56
A23: 7 | B23: 0.5714 | C23: 0.4286 | D23: =B23+C23 -> 1 | E23: =B23*$C$5+C23*$C$6 -> 0.23610594 | F23: =SQRT((B23^2)*($C$7^2) + (C23^2)*($C$8^2) + 2*B23*C23*$C$9*$C$7*$C$8) -> 0.14993789 | G23: =(E23-$C$4)/F23 -> 1.3312575 | H23: =(H22+$C$13)*(1+E23) -> 191224.07 | I23: =(I22+$C$13)*(1+E23-F23) -> 100547.53 | J23: =(J22+$C$13)*(1+E23+F23) -> 357408.81
A24: 8 | B24: 0.55 | C24: 0.45 | D24: =B24+C24 -> 1 | E24: =B24*$C$5+C24*$C$6 -> 0.22840584 | F24: =SQRT((B24^2)*($C$7^2) + (C24^2)*($C$8^2) + 2*B24*C24*$C$9*$C$7*$C$8) -> 0.1443475 | G24: =(E24-$C$4)/F24 -> 1.3294712 | H24: =(H23+$C$13)*(1+E24) -> 247184.82 | I24: =(I23+$C$13)*(1+E24-F24) -> 119839.97 | J24: =(J23+$C$13)*(1+E24+F24) -> 504361.68
A25: 9 | B25: 0.5286 | C25: 0.4714 | D25: =B25+C25 -> 1 | E25: =B25*$C$5+C25*$C$6 -> 0.22070574 | F25: =SQRT((B25^2)*($C$7^2) + (C25^2)*($C$8^2) + 2*B25*C25*$C$9*$C$7*$C$8) -> 0.13875729 | G25: =(E25-$C$4)/F25 -> 1.3275392 | H25: =(H24+$C$13)*(1+E25) -> 313946.98 | I25: =(I24+$C$13)*(1+E25-F25) -> 140480.15 | J25: =(J24+$C$13)*(1+E25+F25) -> 699255.68
A26: 10 | B26: 0.5071 | C26: 0.4929 | D26: =B26+C26 -> 1 | E26: =B26*$C$5+C26*$C$6 -> 0.21296966 | F26: =SQRT((B26^2)*($C$7^2) + (C26^2)*($C$8^2) + 2*B26*C26*$C$9*$C$7*$C$8) -> 0.13314116 | G26: =(E26-$C$4)/F26 -> 1.3254329 | H26: =(H25+$C$13)*(1+E26) -> 392937.86 | I26: =(I25+$C$13)*(1+E26-F26) -> 162492.76 | J26: =(J25+$C$13)*(1+E26+F26) -> 954736.75
A27: 11 | B27: 0.4857 | C27: 0.5143 | D27: =B27+C27 -> 1 | E27: =B27*$C$5+C27*$C$6 -> 0.20526956 | F27: =SQRT((B27^2)*($C$7^2) + (C27^2)*($C$8^2) + 2*B27*C27*$C$9*$C$7*$C$8) -> 0.12755136 | G27: =(E27-$C$4)/F27 -> 1.3231498 | H27: =(H26+$C$13)*(1+E27) -> 485648.74 | I27: =(I26+$C$13)*(1+E27-F27) -> 185898.59 | J27: =(J26+$C$13)*(1+E27+F27) -> 1285821.3
A28: 12 | B28: 0.4643 | C28: 0.5357 | D28: =B28+C28 -> 1 | E28: =B28*$C$5+C28*$C$6 -> 0.19756947 | F28: =SQRT((B28^2)*($C$7^2) + (C28^2)*($C$8^2) + 2*B28*C28*$C$9*$C$7*$C$8) -> 0.12196183 | G28: =(E28-$C$4)/F28 -> 1.3206548 | H28: =(H27+$C$13)*(1+E28) -> 593573.8 | I28: =(I27+$C$13)*(1+E28-F28) -> 210710.02 | J28: =(J27+$C$13)*(1+E28+F28) -> 1709876.8
A29: 13 | B29: 0.4429 | C29: 0.5571 | D29: =B29+C29 -> 1 | E29: =B29*$C$5+C29*$C$6 -> 0.18986937 | F29: =SQRT((B29^2)*($C$7^2) + (C29^2)*($C$8^2) + 2*B29*C29*$C$9*$C$7*$C$8) -> 0.11637258 | G29: =(E29-$C$4)/F29 -> 1.3179167 | H29: =(H28+$C$13)*(1+E29) -> 718173.98 | I29: =(I28+$C$13)*(1+E29-F29) -> 236931.49 | J29: =(J28+$C$13)*(1+E29+F29) -> 2246575.2
... A31: 15 | B31: 0.4 | C31: 0.6 | D31: =B31+C31 -> 1 | E31: =B31*$C$5+C31*$C$6 -> 0.17443319 | F31: =SQRT((B31^2)*($C$7^2) + (C31^2)*($C$8^2) + 2*B31*C31*$C$9*$C$7*$C$8) -> 0.10516902 | G31: =(E31-$C$4)/F31 -> 1.3115382 | H31: =(H30+$C$13)*(1+E31) -> 1022694.9 | I31: =(I30+$C$13)*(1+E31-F31) -> 293573.33 | J31: =(J30+$C$13)*(1+E31+F31) -> 3746042.4
A34: REBALANCING METHODOLOGY
A35: Portfolio rebalances annually to target allocation weights
A36: New $10,000 contribution added at start of each year | E36: Glide Path (Stock Vs Bonds)
A37: Weights reset to glide path targets after rebalancing
A38: Linear transition: Stock weight decreases 2.14% per year
A40: METHODOLOGY NOTES
A41: Expected returns based on historical analysis adjusted for forward estimates
A42: Volatility calculated from historical daily returns, annualized (x sqrt252)
A43: Sharpe Ratio = (Portfolio Return - Risk-Free Rate) / Portfolio Volatility
A44: Risk-free rate: 3.65% (10-year Treasury benchmark)

Sheet Summary
A1: Assets | B1: Annualized Return | C1: Annualized Volatility(Sigma) | D1: Sharpe Ratio | E1: Variance | F1: Beta | J1: AAPL | K1: AGG | L1: AMZN | M1: BND | N1: GOOGL | O1: JNJ | P1: JPM | Q1: MSFT | R1: NVDA | S1: PG | T1: QQQ | U1: SCHP | V1: SPTL | W1: TLT | X1: TSLA | Y1: VEA | Z1: VOO | AA1: XOM
A2: AAPL | B2: =AVERAGE('Daily Returns'!B$3:B$1510) * 252 -> 0.36532045 | C2: =_xlfn.STDEV.P('Daily Returns'!B$3:B$1510) * SQRT(252) -> 0.30837763 | D2: =(B2 - 0.0365) / C2 -> 1.0662915 | E2: =C2^2 -> 0.095096762 | F2: =SLOPE('Daily Returns'!B$3:B$1510, 'Daily Returns'!R$3:R$1510) -> 1.1996058 | I2: AAPL | J2: =VARP('Daily Returns'!$B$2:$B$1510) -> 0.0003773681 | K2: 9.6140148e-06 | L2: 0.00024661293 | M2: 1.1588319e-05 | N2: 0.00024385552 | O2: 8.4605352e-05 | P2: 0.00015484545 | Q2: 0.00026061321 | R2: 0.00038305354 | S2: 9.9485102e-05 | T2: 0.00024862973 | U2: 5.4200029e-06 | V2: -2.2409769e-05 | W2: -2.2943099e-05 | X2: 0.00036746945 | Y2: 0.00014406421 | Z2: 0.00019218852 | AA2: 0.00011476338
A3: AGG | B3: =AVERAGE('Daily Returns'!C$3:C$1510) * 252 -> 0.01280733 | C3: =_xlfn.STDEV.P('Daily Returns'!C$3:C$1510) * SQRT(252) -> 0.063747504 | D3: =(B3 - 0.0365) / C3 -> -0.37166428 | E3: =C3^2 -> 0.0040637443 | F3: =SLOPE('Daily Returns'!C$3:C$1510, 'Daily Returns'!R$3:R$1510) -> 0.048437083 | I3: AGG | J3: 9.6140148e-06 | K3: =VARP('Daily Returns'!$C$2:$C$1510) -> 1.612597e-05 | L3: 1.3126047e-05 | M3: 1.582849e-05 | N3: 1.000817e-05 | O3: 1.7181679e-06 | P3: -1.1219495e-06 | Q3: 9.97905e-06 | R3: 1.5470811e-05 | S3: 6.0536382e-06 | T3: 9.8589126e-06 | U3: 1.2752906e-05 | V3: 3.3529048e-05 | W3: 3.577981e-05 | X3: 1.9576406e-05 | Y3: 1.021021e-05 | Z3: 7.760092e-06 | AA3: -2.5826851e-06
A4: AMZN | B4: =AVERAGE('Daily Returns'!D$3:D$1510) * 252 -> 0.23479256 | C4: =_xlfn.STDEV.P('Daily Returns'!D$3:D$1510) * SQRT(252) -> 0.34127335 | D4: =(B4 - 0.0365) / C4 -> 0.58103734 | E4: =C4^2 -> 0.1164675 | F4: =SLOPE('Daily Returns'!D$3:D$1510, 'Daily Returns'!$R$3:$R$1510) -> 1.0963535 | I4: AMZN | J4: 0.00024661293 | K4: 1.3126047e-05 | L4: =VARP('Daily Returns'!$D$2:$D$1510) -> 0.00046217262 | M4: 1.4128402e-05 | N4: 0.00027236945 | O4: 4.8575544e-05 | P4: 0.0001148991 | Q4: 0.00026776092 | R4: 0.00040605649 | S4: 6.3756519e-05 | T4: 0.00025409919 | U4: 1.0804295e-05 | V4: -4.9547666e-06 | W4: -5.2984959e-06 | X4: 0.0003673467 | Y4: 0.00012927798 | Z4: 0.00017564649 | AA4: 6.3946751e-05
A5: BND | B5: =AVERAGE('Daily Returns'!E$3:E$1510) * 252 -> 0.013516327 | C5: =_xlfn.STDEV.P('Daily Returns'!E$3:E$1510) * SQRT(252) -> 0.065482895 | D5: =(B5 - 0.0365) / C5 -> -0.35098742 | E5: =C5^2 -> 0.0042880095 | F5: =SLOPE('Daily Returns'!E$3:E$1510, 'Daily Returns'!$R$3:$R$1510) -> 0.05819552 | I5: BND | J5: 1.1588319e-05 | K5: 1.582849e-05 | L5: 1.4128402e-05 | M5: =VARP('Daily Returns'!$E$2:$E$1510) -> 1.7015911e-05 | N5: 1.11134e-05 | O5: 4.1247962e-06 | P5: 1.1230272e-06 | Q5: 1.2377918e-05 | R5: 1.6203383e-05 | S5: 1.0082625e-05 | T5: 1.1312981e-05 | U5: 1.2730082e-05 | V5: 3.2670203e-05 | W5: 3.4714822e-05 | X5: 1.3931148e-05 | Y5: 1.1080692e-05 | Z5: 9.3234885e-06 | AA5: -3.1654065e-06
A6: GOOGL | B6: =AVERAGE('Daily Returns'!F$3:F$1510) * 252 -> 0.2646889 | C6: =_xlfn.STDEV.P('Daily Returns'!F$3:F$1510) * SQRT(252) -> 0.31202217 | D6: =(B6 - 0.0365) / C6 -> 0.7313227 | E6: =C6^2 -> 0.097357835 | F6: =SLOPE('Daily Returns'!F$3:F$1510, 'Daily Returns'!$R$3:$R$1510) -> 1.1411909 | I6: GOOGL | J6: 0.00024385552 | K6: 1.000817e-05 | L6: 0.00027236945 | M6: 1.11134e-05 | N6: =VARP('Daily Returns'!$F$2:$F$1510) -> 0.00038634061 | O6: 6.8672453e-05 | P6: 0.00015316183 | Q6: 0.00026440972 | R6: 0.000372751 | S6: 8.118512e-05 | T6: 0.00023890954 | U6: 6.9979434e-06 | V6: -1.8937911e-05 | W6: -1.9473843e-05 | X6: 0.00030716518 | Y6: 0.00013989659 | Z6: 0.00018282988 | AA6: 0.00010750931
A7: JNJ | B7: =AVERAGE('Daily Returns'!G$3:G$1510) * 252 -> 0.065375084 | C7: =_xlfn.STDEV.P('Daily Returns'!G$3:G$1510) * SQRT(252) -> 0.19147747 | D7: =(B7 - 0.0365) / C7 -> 0.15080147 | E7: =C7^2 -> 0.036663621 | F7: =SLOPE('Daily Returns'!G$3:G$1510, 'Daily Returns'!$R$3:$R$1510) -> 0.48845859 | I7: JNJ | J7: 8.4605352e-05 | K7: 1.7181679e-06 | L7: 4.8575544e-05 | M7: 4.1247962e-06 | N7: 6.8672453e-05 | O7: =VARP('Daily Returns'!$G$2:$G$1510) -> 0.00014549056 | P7: 9.116294e-05 | Q7: 8.1909321e-05 | R7: 6.0578399e-05 | S7: 8.8098768e-05 | T7: 6.8706936e-05 | U7: -8.9374395e-07 | V7: -1.671386e-05 | W7: -1.7401163e-05 | X7: 3.8025565e-05 | Y7: 6.1228459e-05 | Z7: 7.8255818e-05 | AA7: 7.2092085e-05
A8: JPM | B8: =AVERAGE('Daily Returns'!H$3:H$1510) * 252 -> 0.22314162 | C8: =_xlfn.STDEV.P('Daily Returns'!H$3:H$1510) * SQRT(252) -> 0.30651878 | D8: =(B8 - 0.0365) / C8 -> 0.60890763 | E8: =C8^2 -> 0.093953762 | F8: =SLOPE('Daily Returns'!H$3:H$1510, 'Daily Returns'!$R$3:$R$1510) -> 1.0825467 | I8: JPM | J8: 0.00015484545 | K8: -1.1219495e-06 | L8: 0.0001148991 | M8: 1.1230272e-06 | N8: 0.00015316183 | O8: 9.116294e-05 | P8: =VARP('Daily Returns'!$H$2:$H$1510) -> 0.00037283239 | Q8: 0.00014948802 | R8: 0.00021220474 | S8: 8.5572349e-05 | T8: 0.00015095619 | U8: -3.184354e-06 | V8: -6.171914e-05 | W8: -6.3244752e-05 | X8: 0.00021111105 | Y8: 0.00015858986 | Z8: 0.00017343451 | AA8: 0.00022231336
A9: MSFT | B9: =AVERAGE('Daily Returns'!I$3:I$1510) * 252 -> 0.29195414 | C9: =_xlfn.STDEV.P('Daily Returns'!I$3:I$1510) * SQRT(252) -> 0.28994744 | D9: =(B9 - 0.0365) / C9 -> 0.88103603 | E9: =C9^2 -> 0.084069518 | F9: =SLOPE('Daily Returns'!I$3:I$1510, 'Daily Returns'!$R$3:$R$1510) -> 1.1825608 | I9: MSFT | J9: 0.00026061321 | K9: 9.97905e-06 | L9: 0.00026776092 | M9: 1.2377918e-05 | N9: 0.00026440972 | O9: 8.1909321e-05 | P9: 0.00014948802 | Q9: =VARP('Daily Returns'!$I$2:$I$1510) -> 0.0003336092 | R9: 0.00040054948 | S9: 0.00010305172 | T9: 0.00024610208 | U9: 5.2822504e-06 | V9: -2.1259298e-05 | W9: -2.1779294e-05 | X9: 0.00032047869 | Y9: 0.00014130649 | Z9: 0.00018945775 | AA9: 9.3865446e-05
A10: NVDA | B10: =AVERAGE('Daily Returns'!J$3:J$1510) * 252 -> 0.75367981 | C10: =_xlfn.STDEV.P('Daily Returns'!J$3:J$1510) * SQRT(252) -> 0.5187595 | D10: =(B10 - 0.0365) / C10 -> 1.38249 | E10: =C10^2 -> 0.26911142 | F10: =SLOPE('Daily Returns'!J$3:J$1510, 'Daily Returns'!$R$3:$R$1510) -> 1.7879976 | I10: NVDA | J10: 0.00038305354 | K10: 1.5470811e-05 | L10: 0.00040605649 | M10: 1.6203383e-05 | N10: 0.000372751 | O10: 6.0578399e-05 | P10: 0.00021220474 | Q10: 0.00040054948 | R10: =VARP('Daily Returns'!$J$2:$J$1510) -> 0.0010679024 | S10: 9.4046519e-05 | T10: 0.00039982143 | U10: 8.9651211e-06 | V10: -2.25626e-05 | W10: -2.2591119e-05 | X10: 0.0006019799 | Y10: 0.00022299789 | Z10: 0.00028645461 | AA10: 0.00013393343
A11: PG | B11: =AVERAGE('Daily Returns'!K$3:K$1510) * 252 -> 0.14683046 | C11: =_xlfn.STDEV.P('Daily Returns'!K$3:K$1510) * SQRT(252) -> 0.20257114 | D11: =(B11 - 0.0365) / C11 -> 0.54465045 | E11: =C11^2 -> 0.041035068 | F11: =SLOPE('Daily Returns'!K$3:K$1510, 'Daily Returns'!$R$3:$R$1510) -> 0.55026598 | I11: PG | J11: 9.9485102e-05 | K11: 6.0536382e-06 | L11: 6.3756519e-05 | M11: 1.0082625e-05 | N11: 8.118512e-05 | O11: 8.8098768e-05 | P11: 8.5572349e-05 | Q11: 0.00010305172 | R11: 9.4046519e-05 | S11: =VARP('Daily Returns'!$K$2:$K$1510) -> 0.00016283757 | T11: 8.4430974e-05 | U11: 1.2038167e-06 | V11: -8.1207375e-06 | W11: -8.351527e-06 | X11: 5.0168386e-05 | Y11: 6.7650603e-05 | Z11: 8.8157964e-05 | AA11: 5.6553956e-05
A12: QQQ | B12: =AVERAGE('Daily Returns'!L$3:L$1510) * 252 -> 0.23727152 | C12: =_xlfn.STDEV.P('Daily Returns'!L$3:L$1510) * SQRT(252) -> 0.24328327 | D12: =(B12 - 0.0365) / C12 -> 0.82525822 | E12: =C12^2 -> 0.05918675 | F12: =SLOPE('Daily Returns'!L$3:L$1510, 'Daily Returns'!$R$3:$R$1510) -> 1.1255759 | I12: QQQ | J12: 0.00024862973 | K12: 9.8589126e-06 | L12: 0.00025409919 | M12: 1.1312981e-05 | N12: 0.00023890954 | O12: 6.8706936e-05 | P12: 0.00015095619 | Q12: 0.00024610208 | R12: 0.00039982143 | S12: 8.4430974e-05 | T12: =VARP('Daily Returns'!$L$2:$L$1510) -> 0.00023486806 | U12: 6.1118872e-06 | V12: -1.7719232e-05 | W12: -1.8138113e-05 | X12: 0.00035962376 | Y12: 0.00014088208 | Z12: 0.00018032821 | AA12: 0.00010346129
A13: SCHP | B13: =AVERAGE('Daily Returns'!M$3:M$1510) * 252 -> 0.030506116 | C13: =_xlfn.STDEV.P('Daily Returns'!M$3:M$1510) * SQRT(252) -> 0.065570424 | D13: =(B13 - 0.0365) / C13 -> -0.091411392 | E13: =C13^2 -> 0.0042994805 | F13: =SLOPE('Daily Returns'!M$3:M$1510, 'Daily Returns'!$R$3:$R$1510) -> 0.027057466 | I13: SCHP | J13: 5.4200029e-06 | K13: 1.2752906e-05 | L13: 1.0804295e-05 | M13: 1.2730082e-05 | N13: 6.9979434e-06 | O13: -8.9374395e-07 | P13: -3.184354e-06 | Q13: 5.2822504e-06 | R13: 8.9651211e-06 | S13: 1.2038167e-06 | T13: 6.1118872e-06 | U13: =VARP('Daily Returns'!$M$2:$M$1510) -> 1.7061431e-05 | V13: 2.9857847e-05 | W13: 3.1950543e-05 | X13: 1.6009062e-05 | Y13: 7.2518616e-06 | Z13: 4.3348692e-06 | AA13: 2.5247992e-06
A14: SPTL | B14: =AVERAGE('Daily Returns'!N$3:N$1510) * 252 -> -0.010184698 | C14: =_xlfn.STDEV.P('Daily Returns'!N$3:N$1510) * SQRT(252) -> 0.15983979 | D14: =(B14 - 0.0365) / C14 -> -0.29207181 | E14: =C14^2 -> 0.025548759 | F14: =SLOPE('Daily Returns'!N$3:N$1510, 'Daily Returns'!$R$3:$R$1510) -> -0.1472769 | I14: SPTL | J14: -2.2409769e-05 | K14: 3.3529048e-05 | L14: -4.9547666e-06 | M14: 3.2670203e-05 | N14: -1.8937911e-05 | O14: -1.671386e-05 | P14: -6.171914e-05 | Q14: -2.1259298e-05 | R14: -2.25626e-05 | S14: -8.1207375e-06 | T14: -1.7719232e-05 | U14: 2.9857847e-05 | V14: =VARP('Daily Returns'!$N$2:$N$1510) -> 0.00010138397 | W14: 0.00010816994 | X14: -1.539266e-05 | Y14: -1.6605072e-05 | Z14: -2.3595193e-05 | AA14: -5.5455828e-05
A15: TLT | B15: =AVERAGE('Daily Returns'!O$3:O$1510) * 252 -> -0.015321897 | C15: =_xlfn.STDEV.P('Daily Returns'!O$3:O$1510) * SQRT(252) -> 0.17111208 | D15: =(B15 - 0.0365) / C15 -> -0.30285352 | E15: =C15^2 -> 0.029279345 | F15: =SLOPE('Daily Returns'!O$3:O$1510, 'Daily Returns'!$R$3:$R$1510) -> -0.15112748 | I15: TLT | J15: -2.2943099e-05 | K15: 3.577981e-05 | L15: -5.2984959e-06 | M15: 3.4714822e-05 | N15: -1.9473843e-05 | O15: -1.7401163e-05 | P15: -6.3244752e-05 | Q15: -2.1779294e-05 | R15: -2.2591119e-05 | S15: -8.351527e-06 | T15: -1.8138113e-05 | U15: 3.1950543e-05 | V15: 0.00010816994 | W15: =VARP('Daily Returns'!$O$2:$O$1510) -> 0.00011618788 | X15: -1.4183482e-05 | Y15: -1.6734505e-05 | Z15: -2.4212093e-05 | AA15: -5.7144021e-05
A16: TSLA | B16: =AVERAGE('Daily Returns'!P$3:P$1510) * 252 -> 0.70977416 | C16: =_xlfn.STDEV.P('Daily Returns'!P$3:P$1510) * SQRT(252) -> 0.6446344 | D16: =(B16 - 0.0365) / C16 -> 1.0444279 | E16: =C16^2 -> 0.41555351 | F16: =SLOPE('Daily Returns'!P$3:P$1510, 'Daily Returns'!$R$3:$R$1510) -> 1.554866 | I16: TSLA | J16: 0.00036746945 | K16: 1.9576406e-05 | L16: 0.0003673467 | M16: 1.3931148e-05 | N16: 0.00030716518 | O16: 3.8025565e-05 | P16: 0.00021111105 | Q16: 0.00032047869 | R16: 0.0006019799 | S16: 5.0168386e-05 | T16: 0.00035962376 | U16: 1.6009062e-05 | V16: -1.539266e-05 | W16: -1.4183482e-05 | X16: =VARP('Daily Returns'!$P$2:$P$1510) -> 0.0016490219 | Y16: 0.00020464161 | Z16: 0.00024910467 | AA16: 0.00012326062
A17: VEA | B17: =AVERAGE('Daily Returns'!Q$3:Q$1510) * 252 -> 0.091096127 | C17: =_xlfn.STDEV.P('Daily Returns'!Q$3:Q$1510) * SQRT(252) -> 0.18878554 | D17: =(B17 - 0.0365) / C17 -> 0.28919655 | E17: =C17^2 -> 0.035639982 | F17: =SLOPE('Daily Returns'!Q$3:Q$1510, 'Daily Returns'!$R$3:$R$1510) -> 0.82290257 | I17: VEA | J17: 0.00014406421 | K17: 1.021021e-05 | L17: 0.00012927798 | M17: 1.1080692e-05 | N17: 0.00013989659 | O17: 6.1228459e-05 | P17: 0.00015858986 | Q17: 0.00014130649 | R17: 0.00022299789 | S17: 6.7650603e-05 | T17: 0.00014088208 | U17: 7.2518616e-06 | V17: -1.6605072e-05 | W17: -1.6734505e-05 | X17: 0.00020464161 | Y17: =VARP('Daily Returns'!$Q$2:$Q$1510) -> 0.0001414285 | Z17: 0.000131837 | AA17: 0.0001328279
A18: VOO | B18: =AVERAGE('Daily Returns'!R$3:R$1510) * 252 -> 0.17966628 | C18: =_xlfn.STDEV.P('Daily Returns'!R$3:R$1510) * SQRT(252) -> 0.20092997 | D18: =(B18 - 0.0365) / C18 -> 0.7125183 | E18: =C18^2 -> 0.040372852 | F18: =SLOPE('Daily Returns'!R$3:R$1510, 'Daily Returns'!$R$3:$R$1510) -> 1 | I18: VOO | J18: 0.00019218852 | K18: 7.760092e-06 | L18: 0.00017564649 | M18: 9.3234885e-06 | N18: 0.00018282988 | O18: 7.8255818e-05 | P18: 0.00017343451 | Q18: 0.00018945775 | R18: 0.00028645461 | S18: 8.8157964e-05 | T18: 0.00018032821 | U18: 4.3348692e-06 | V18: -2.3595193e-05 | W18: -2.4212093e-05 | X18: 0.00024910467 | Y18: 0.000131837 | Z18: =VARP('Daily Returns'!$R$2:$R$1510) -> 0.00016020973 | AA18: 0.00013496764
A19: XOM | B19: =AVERAGE('Daily Returns'!S$3:S$1510) * 252 -> 0.1700689 | C19: =_xlfn.STDEV.P('Daily Returns'!S$3:S$1510) * SQRT(252) -> 0.3224467 | D19: =(B19 - 0.0365) / C19 -> 0.4142356 | E19: =C19^2 -> 0.10397187 | F19: =SLOPE('Daily Returns'!S$3:S$1510, 'Daily Returns'!$R$3:$R$1510) -> 0.84244346 | I19: XOM | J19: 0.00011476338 | K19: -2.5826851e-06 | L19: 6.3946751e-05 | M19: -3.1654065e-06 | N19: 0.00010750931 | O19: 7.2092085e-05 | P19: 0.00022231336 | Q19: 9.3865446e-05 | R19: 0.00013393343 | S19: 5.6553956e-05 | T19: 0.00010346129 | U19: 2.5247992e-06 | V19: -5.5455828e-05 | W19: -5.7144021e-05 | X19: 0.00012326062 | Y19: 0.0001328279 | Z19: 0.00013496764 | AA19: =VARP('Daily Returns'!$S$2:$S$1510) -> 0.00041258679
J23: Overall Portfolio
A25: Dots | B25: X(Risk) | C25: Y(Return) | J25: Portfolio Return | K25: =SUMPRODUCT(K31:K48, L31:L48) -> 0.28237849 | M25: 0,183535226531224
A26: Risk-Free Point | B26: 0 | C26: 0.0365 | J26: Portfolio Variance | K26: =0.0336 -> 0.0336
A27: Optimal Portfolio | B27: 0.184 | C27: 0.282 | J27: Portfolio Risk (SD) | K27: =SQRT(K26) -> 0.18330303
J28: Sharpe Ratio | K28: =(K25-0.0365)/K27 -> 1.3413772
J30: Assets | K30: Weights | L30: Returns
J31: AAPL | K31: 0.105 | L31: 0.36532045
J32: AMZN | K32: 0 | L32: 0.23479256
J33: GOOGL | K33: 0.0098110922 | L33: 0.2646889
J34: JNJ | K34: 0.00057579475 | L34: 0.065375084
J35: JPM | K35: 0.084843181 | L35: 0.22314162
J36: MSFT | K36: 0.105 | L36: 0.29195414
J37: NVDA | K37: 0.105 | L37: 0.75367981
J38: PG | K38: 0.105 | L38: 0.14683046
J39: TSLA | K39: 0.105 | L39: 0.70977416
J40: XOM | K40: 0.079769939 | L40: 0.1700689
J41: QQQ | K41: 0 | L41: 0.23727152
J42: VEA | K42: 0 | L42: 0.091096127
... J48: TLT | K48: 0 | L48: -0.015321897
K49: =SUM(K31:K48) -> 1

Sheet Optimals
A1: Optimal Risky Portfolio
A2: Assets | B2: Weight | C2: Constraint | D2: Variance
A3: Stock Optimal Risky | B3: 0.7 | C3: 0.15 | D3: 0.068603031
A4: Bond ETF Optimal Risky | B4: 0.3
A5: Expected Return | B5: 0.28237849
A6: Standard Deviation | B6: 0.18353523
A7: Sharpe Ratio | B7: 1.34
A9: Optimal Risky Portfolio
A10: Assets | B10: Weight | C10: Constraint | D10: Variance
A11: AAPL | B11: 0.15 | C11: 0.15 | D11: 0.068603031
A12: AMZN | B12: 0
A13: GOOGL | B13: 0.014015846
A14: JNJ | B14: 0.00082256393
A15: JPM | B15: 0.12120454
A16: MSFT | B16: 0.15
A17: NVDA | B17: 0.15
A18: PG | B18: 0.15
A19: TSLA | B19: 0.15
A20: XOM | B20: 0.11395706
A21: QQQ | B21: 0
A22: VEA | B22: 0
A23: VOO | B23: 0
... A26: Sharpe Ratio | B26: 1.3508757
A29: Optimal Risky Portfolio
A30: Assets | B30: Weight | C30: Constraint | D30: Variance
A31: AGG | B31: 0 | D31: 0.0042994805
A32: BND | B32: 0
A33: SCHP | B33: 1
A34: SPTL | B34: 0
A35: TLT | B35: 0
A36: Expected Return of Portfolio | B36: 0.0062646357
A37: Standard Deviation of Portfolio | B37: 0.079149451
A38: Sharpe Ratio | B38: -0.46115291

Sheet Stocks
A1: Date | B1: AAPL | C1: AMZN | D1: GOOGL | E1: JNJ | F1: JPM | G1: MSFT | H1: NVDA | I1: PG | J1: TSLA | K1: XOM | L1: QQQ | M1: VEA | N1: VOO | Q1: AAPL | R1: AMZN | S1: GOOGL | T1: JNJ | U1: JPM | V1: MSFT | W1: NVDA | X1: PG | Y1: TSLA | Z1: XOM | AA1: QQQ | AB1: VEA | AC1: VOO | AE1: Total
A2: 43467 | P2: AVERAGE | Q2: =AVERAGE(B3:B1510) -> 0.0014496843 | R2: =AVERAGE(C3:C1510) -> 0.00093171651 | S2: =AVERAGE(D3:D1510) -> 0.0010503528 | T2: =AVERAGE(E3:E1510) -> 0.00025942494 | U2: =AVERAGE(F3:F1510) -> 0.00088548263 | V2: =AVERAGE(G3:G1510) -> 0.0011585482 | W2: =AVERAGE(H3:H1510) -> 0.0029907929 | X2: =AVERAGE(I3:I1510) -> 0.00058266057 | ... AC2: =AVERAGE(N3:N1510) -> 0.00071296143 | AE2: =AVERAGE(Q2:AA2) -> 0.0012492416
A3: 43468 | B3: =(Prices!B3 - Prices!B2) / Prices!B2 -> -0.099607371 | C3: =(Prices!D3 - Prices!D2) / Prices!D2 -> -0.025241498 | D3: =(Prices!F3 - Prices!F2) / Prices!F2 -> -0.027695588 | E3: =(Prices!G3 - Prices!G2) / Prices!G2 -> -0.015890362 | F3: =(Prices!H3 - Prices!H2) / Prices!H2 -> -0.014212072 | G3: =(Prices!I3 - Prices!I2) / Prices!I2 -> -0.036787978 | H3: =(Prices!J3 - Prices!J2) / Prices!J2 -> -0.060416834 | I3: =(Prices!K3 - Prices!K2) / Prices!K2 -> -0.0070112329 | J3: =(Prices!P3 - Prices!P2) / Prices!P2 -> -0.031471713 | K3: =(Prices!S3 - Prices!S2) / Prices!S2 -> -0.015353787 | L3: -0.03267111 | M3: -0.0080967925 | N3: -0.023870461 | P3: STD. DEV. | Q3: =_xlfn.STDEV.P(B3:B1510) -> 0.019425965 | R3: =_xlfn.STDEV.P(C3:C1510) -> 0.0214982 | S3: =_xlfn.STDEV.P(D3:D1510) -> 0.019655549 | T3: =_xlfn.STDEV.P(E3:E1510) -> 0.012061947 | U3: =_xlfn.STDEV.P(F3:F1510) -> 0.019308868 | V3: =_xlfn.STDEV.P(G3:G1510) -> 0.018264972 | W3: =_xlfn.STDEV.P(H3:H1510) -> 0.032678777 | X3: =_xlfn.STDEV.P(I3:I1510) -> 0.012760783 | ... AC3: =_xlfn.STDEV.P(N3:N1510) -> 0.012657398 | AE3: =AVERAGE(Q3:Z3) -> 0.021657544
A4: 43469 | B4: =(Prices!B4 - Prices!B3) / Prices!B3 -> 0.042689351 | C4: =(Prices!D4 - Prices!D3) / Prices!D3 -> 0.050063999 | D4: =(Prices!F4 - Prices!F3) / Prices!F3 -> 0.051293507 | E4: =(Prices!G4 - Prices!G3) / Prices!G3 -> 0.016783075 | F4: =(Prices!H4 - Prices!H3) / Prices!H3 -> 0.036865887 | G4: =(Prices!I4 - Prices!I3) / Prices!I3 -> 0.046509241 | H4: =(Prices!J4 - Prices!J3) / Prices!J3 -> 0.06406739 | I4: =(Prices!K4 - Prices!K3) / Prices!K3 -> 0.020410013 | J4: =(Prices!P4 - Prices!P3) / Prices!P3 -> 0.057697391 | K4: =(Prices!S4 - Prices!S3) / Prices!S3 -> 0.036869701 | L4: 0.042785227 | M4: 0.03074832 | N4: 0.033006559 | P4: VARIANCE | Q4: =VAR(B3:B1510) -> 0.00037761851 | R4: =VAR(C3:C1510) -> 0.00046247931 | S4: =VAR(D3:D1510) -> 0.00038659698 | T4: =VAR(E3:E1510) -> 0.0001455871 | U4: =VAR(F3:F1510) -> 0.00037307979 | V4: =VAR(G3:G1510) -> 0.00033383057 | W4: =VAR(H3:H1510) -> 0.0010686111 | X4: =VAR(I3:I1510) -> 0.00016294563 | Y4: =VAR(J3:J1510) -> 0.0016501161 | Z4: =VAR(K3:K1511) -> 0.00041286057 | AA4: =VAR(L3:L1511) -> 0.00023502391 | AB4: =VAR(M3:M1511) -> 0.00014152235 | AC4: =VAR(N3:N1511) -> 0.00016031604 | AE4: =AVERAGE(Q4:Z4) -> 0.00053737256
A5: 43472 | B5: =(Prices!B5 - Prices!B4) / Prices!B4 -> -0.0022259801 | C5: =(Prices!D5 - Prices!D4) / Prices!D4 -> 0.034353414 | D5: =(Prices!F5 - Prices!F4) / Prices!F4 -> -0.0019942937 | E5: =(Prices!G5 - Prices!G4) / Prices!G4 -> -0.0064144918 | F5: =(Prices!H5 - Prices!H4) / Prices!H4 -> 0.00069514534 | G5: =(Prices!I5 - Prices!I4) / Prices!I4 -> 0.0012755594 | H5: =(Prices!J5 - Prices!J4) / Prices!J4 -> 0.052940737 | I5: =(Prices!K5 - Prices!K4) / Prices!K4 -> -0.0040002372 | J5: =(Prices!P5 - Prices!P4) / Prices!P4 -> 0.054361239 | K5: =(Prices!S5 - Prices!S4) / Prices!S4 -> 0.0052001691 | L5: 0.011905505 | M5: 0.0031677512 | N5: 0.0075029854 | P5: ANNUAL Returns | Q5: =Q2 * 252 -> 0.36532045 | R5: =R2 * 252 -> 0.23479256 | S5: =S2 * 252 -> 0.2646889 | T5: =T2 * 252 -> 0.065375084 | U5: =U2 * 252 -> 0.22314162 | V5: =V2 * 252 -> 0.29195414 | W5: =W2 * 252 -> 0.75367981 | X5: =X2 * 252 -> 0.14683046 | ... AC5: =AC2 * 252 -> 0.17966628 | AE5: =AVERAGE(Q5:Z5) -> 0.32256261
A6: 43473 | B6: =(Prices!B6 - Prices!B5) / Prices!B5 -> 0.019063443 | C6: =(Prices!D6 - Prices!D5) / Prices!D5 -> 0.01661236 | D6: =(Prices!F6 - Prices!F5) / Prices!F5 -> 0.0087831676 | E6: =(Prices!G6 - Prices!G5) / Prices!G5 -> 0.023226685 | F6: =(Prices!H6 - Prices!H5) / Prices!H5 -> -0.0018860346 | G6: =(Prices!I6 - Prices!I5) / Prices!I5 -> 0.0072506802 | H6: =(Prices!J6 - Prices!J5) / Prices!J5 -> -0.024895191 | I6: =(Prices!K6 - Prices!K5) / Prices!K5 -> 0.0036907907 | J6: =(Prices!P6 - Prices!P5) / Prices!P5 -> 0.0011642764 | K6: =(Prices!S6 - Prices!S5) / Prices!S5 -> 0.007270887 | L6: 0.0090456699 | M6: 0.0071055882 | N6: 0.0097151655 | P6: Annual Volatility | Q6: =Q3 * SQRT(252) -> 0.30837763 | R6: =R3 * SQRT(252) -> 0.34127335 | S6: =S3 * SQRT(252) -> 0.31202217 | T6: =T3 * SQRT(252) -> 0.19147747 | U6: =U3 * SQRT(252) -> 0.30651878 | V6: =V3 * SQRT(252) -> 0.28994744 | W6: =W3 * SQRT(252) -> 0.5187595 | X6: =X3 * SQRT(252) -> 0.20257114 | ... AC6: =AC3 * SQRT(252) -> 0.20092997 | AE6: =AVERAGE(Q6:Z6) -> 0.34380286
A7: 43474 | B7: =(Prices!B7 - Prices!B6) / Prices!B6 -> 0.016981325 | C7: =(Prices!D7 - Prices!D6) / Prices!D6 -> 0.0017143547 | D7: =(Prices!F7 - Prices!F6) / Prices!F6 -> -0.0034274636 | E7: =(Prices!G7 - Prices!G6) / Prices!G6 -> -0.0079255915 | F7: =(Prices!H7 - Prices!H6) / Prices!H6 -> -0.001690356 | G7: =(Prices!I7 - Prices!I6) / Prices!I6 -> 0.014299726 | H7: =(Prices!J7 - Prices!J6) / Prices!J6 -> 0.019666581 | I7: =(Prices!K7 - Prices!K6) / Prices!K6 -> -0.016331439 | J7: =(Prices!P7 - Prices!P6) / Prices!P6 -> 0.0094826254 | K7: =(Prices!S7 - Prices!S6) / Prices!S6 -> 0.0052746342 | L7: 0.0081496084 | M7: 0.012280989 | N7: 0.0046202221 | P7: Weights | Q7: 0.15 | R7: 0 | S7: 0.014015846 | T7: 0.00082256393 | U7: 0.12120454 | V7: 0.15 | W7: 0.15 | X7: 0.15 | Y7: 0.15 | Z7: 0.11395706 | AA7: 0 | AB7: 0 | AC7: 0 | AE7: =SUM(Q7:AC7) -> 1
A8: 43475 | B8: =(Prices!B8 - Prices!B7) / Prices!B7 -> 0.0031962747 | C8: =(Prices!D8 - Prices!D7) / Prices!D7 -> -0.0019284287 | D8: =(Prices!F8 - Prices!F7) / Prices!F7 -> -0.0026069774 | E8: =(Prices!G8 - Prices!G7) / Prices!G7 -> 0.0060496515 | F8: =(Prices!H8 - Prices!H7) / Prices!H7 -> -9.9514744e-05 | G8: =(Prices!I8 - Prices!I7) / Prices!I7 -> -0.0064258703 | H8: =(Prices!J8 - Prices!J7) / Prices!J7 -> 0.018586143 | I8: =(Prices!K8 - Prices!K7) / Prices!K7 -> 0.0024188689 | J8: =(Prices!P8 - Prices!P7) / Prices!P7 -> 0.019023398 | K8: =(Prices!S8 - Prices!S7) / Prices!S7 -> -0.0051089036 | L8: 0.0028598749 | M8: 0.0041302116 | N8: 0.0041769968
A9: 43476 | B9: =(Prices!B9 - Prices!B8) / Prices!B8 -> -0.0098179812 | C9: =(Prices!D9 - Prices!D8) / Prices!D8 -> -0.0094552313 | D9: =(Prices!F9 - Prices!F8) / Prices!F8 -> -0.013310792 | E9: =(Prices!G9 - Prices!G8) / Prices!G8 -> 0.0003081031 | F9: =(Prices!H9 - Prices!H8) / Prices!H8 -> -0.0047812191 | G9: =(Prices!I9 - Prices!I8) / Prices!I8 -> -0.0077218758 | H9: =(Prices!J9 - Prices!J8) / Prices!J8 -> 0.024788222 | I9: =(Prices!K9 - Prices!K8) / Prices!K8 -> 0.0065811875 | J9: =(Prices!P9 - Prices!P8) / Prices!P8 -> 0.0066383166 | K9: =(Prices!S9 - Prices!S8) / Prices!S8 -> -0.0045800835 | L9: -0.0036580934 | M9: -0.0061698043 | N9: -0.0004620291 | P9: Portfolio Return | Q9: =SUMPRODUCT(Q7:AC7, Q5:AC5) -> 0.3903238
A10: 43479 | B10: =(Prices!B10 - Prices!B9) / Prices!B9 -> -0.015036961 | C10: =(Prices!D10 - Prices!D9) / Prices!D9 -> -0.014232986 | D10: =(Prices!F10 - Prices!F9) / Prices!F9 -> -0.012175112 | E10: =(Prices!G10 - Prices!G9) / Prices!G9 -> -0.011329162 | F10: =(Prices!H10 - Prices!H9) / Prices!H9 -> 0.010309227 | G10: =(Prices!I10 - Prices!I9) / Prices!I9 -> -0.0072958917 | H10: =(Prices!J10 - Prices!J9) / Prices!J9 -> 0.010817767 | I10: =(Prices!K10 - Prices!K9) / Prices!K9 -> -0.0067558292 | J10: =(Prices!P10 - Prices!P9) / Prices!P9 -> -0.037032805 | K10: =(Prices!S10 - Prices!S9) / Prices!S9 -> -0.0012549146 | L10: -0.0088366019 | M10: -0.0051736779 | N10: -0.0055067326 | P10: Portfolio Annual Variance | Q10: {=MMULT(MMULT(Q7:AC7, Q24:AC36), TRANSPOSE(Q7:AC7)) * 252} -> 0.068603031
A11: 43480 | B11: =(Prices!B11 - Prices!B10) / Prices!B10 -> 0.020466665 | C11: =(Prices!D11 - Prices!D10) / Prices!D10 -> 0.035462314 | D11: =(Prices!F11 - Prices!F10) / Prices!F10 -> 0.033285408 | E11: =(Prices!G11 - Prices!G10) / Prices!G10 -> 0.0084190466 | F11: =(Prices!H11 - Prices!H10) / Prices!H10 -> 0.0073313537 | G11: =(Prices!I11 - Prices!I10) / Prices!I10 -> 0.029005247 | H11: =(Prices!J11 - Prices!J10) / Prices!J10 -> -0.0037887863 | I11: =(Prices!K11 - Prices!K10) / Prices!K10 -> 0.0094349927 | J11: =(Prices!P11 - Prices!P10) / Prices!P10 -> 0.029994027 | K11: =(Prices!S11 - Prices!S10) / Prices!S10 -> 0.00055845701 | L11: 0.019526433 | M11: 0.0062403929 | N11: 0.011708565 | P11: Portfolio Annual Risk | Q11: =SQRT(Q10) -> 0.2619218
A12: 43481 | B12: =(Prices!B12 - Prices!B11) / Prices!B11 -> 0.012216571 | C12: =(Prices!D12 - Prices!D11) / Prices!D11 -> 0.0055059978 | D12: =(Prices!F12 - Prices!F11) / Prices!F11 -> 0.0027610832 | E12: =(Prices!G12 - Prices!G11) / Prices!G11 -> -0.010204173 | F12: =(Prices!H12 - Prices!H11) / Prices!H11 -> 0.0080640918 | G12: =(Prices!I12 - Prices!I11) / Prices!I11 -> 0.0035236512 | H12: =(Prices!J12 - Prices!J11) / Prices!J11 -> -0.0068729594 | I12: =(Prices!K12 - Prices!K11) / Prices!K11 -> -0.0069559028 | J12: =(Prices!P12 - Prices!P11) / Prices!P11 -> 0.0047034144 | K12: =(Prices!S12 - Prices!S11) / Prices!S11 -> -0.00041864583 | L12: -0.00018478793 | M12: 0.003100999 | N12: 0.0022142567 | P12: Portfolio Sharpe Ratio | Q12: =(Q9-0.0365)/Q11 -> 1.3508757
A13: 43482 | B13: =(Prices!B13 - Prices!B12) / Prices!B12 -> 0.0059373072 | C13: =(Prices!D13 - Prices!D12) / Prices!D12 -> 0.0056064344 | D13: =(Prices!F13 - Prices!F12) / Prices!F12 -> 0.0088207192 | E13: =(Prices!G13 - Prices!G12) / Prices!G12 -> 0.0082004652 | F13: =(Prices!H13 - Prices!H12) / Prices!H12 -> 0.0040976714 | G13: =(Prices!I13 - Prices!I12) / Prices!I12 -> 0.0070223253 | H13: =(Prices!J13 - Prices!J12) / Prices!J12 -> 0.019349878 | I13: =(Prices!K13 - Prices!K12) / Prices!K12 -> -0.00014325674 | J13: =(Prices!P13 - Prices!P12) / Prices!P12 -> 0.0036410765 | K13: =(Prices!S13 - Prices!S12) / Prices!S12 -> 0.0068396644 | L13: 0.0078840072 | M13: 0.003348481 | N13: 0.0074620924
A14: 43483 | B14: =(Prices!B14 - Prices!B13) / Prices!B13 -> 0.0061596717 | C14: =(Prices!D14 - Prices!D13) / Prices!D13 -> 0.0017598946 | D14: =(Prices!F14 - Prices!F13) / Prices!F13 -> 0.0074421858 | E14: =(Prices!G14 - Prices!G13) / Prices!G13 -> 0.012394541 | F14: =(Prices!H14 - Prices!H13) / Prices!H13 -> 0.016226002 | G14: =(Prices!I14 - Prices!I13) / Prices!I13 -> 0.014982807 | H14: =(Prices!J14 - Prices!J13) / Prices!J13 -> 0.034339583 | I14: =(Prices!K14 - Prices!K13) / Prices!K13 -> 0.00860531 | J14: =(Prices!P14 - Prices!P13) / Prices!P13 -> -0.12971116 | K14: =(Prices!S14 - Prices!S13) / Prices!S13 -> 0.011922938 | L14: 0.0099004711 | M14: 0.01078353 | N14: 0.013448042
A15: 43487 | B15: =(Prices!B15 - Prices!B14) / Prices!B14 -> -0.022446104 | C15: =(Prices!D15 - Prices!D14) / Prices!D14 -> -0.037749087 | D15: =(Prices!F15 - Prices!F14) / Prices!F14 -> -0.025891781 | E15: =(Prices!G15 - Prices!G14) / Prices!G14 -> -0.014461731 | F15: =(Prices!H15 - Prices!H14) / Prices!H14 -> -0.015775603 | G15: =(Prices!I15 - Prices!I14) / Prices!I14 -> -0.018846732 | H15: =(Prices!J15 - Prices!J14) / Prices!J14 -> -0.051997758 | I15: =(Prices!K15 - Prices!K14) / Prices!K14 -> -0.010719851 | J15: =(Prices!P15 - Prices!P14) / Prices!P14 -> -0.01105014 | K15: =(Prices!S15 - Prices!S14) / Prices!S14 -> -0.015070331 | L15: -0.02003038 | M15: -0.015494481 | N15: -0.013310357
A16: 43488 | B16: =(Prices!B16 - Prices!B15) / Prices!B15 -> 0.0040447263 | C16: =(Prices!D16 - Prices!D15) / Prices!D15 -> 0.0048095706 | D16: =(Prices!F16 - Prices!F15) / Prices!F15 -> 0.0053586857 | E16: =(Prices!G16 - Prices!G15) / Prices!G15 -> 0 | F16: =(Prices!H16 - Prices!H15) / Prices!H15 -> -0.0025257766 | G16: =(Prices!I16 - Prices!I15) / Prices!I15 -> 0.0097462333 | H16: =(Prices!J16 - Prices!J15) / Prices!J15 -> 0.0034951153 | I16: =(Prices!K16 - Prices!K15) / Prices!K15 -> 0.048651034 | J16: =(Prices!P16 - Prices!P15) / Prices!P15 -> -0.037903099 | K16: =(Prices!S16 - Prices!S15) / Prices!S15 -> -0.0082071181 | L16: 0.001296735 | M16: 0.0051602092 | N16: 0.0014896745
A17: 43489 | B17: =(Prices!B17 - Prices!B16) / Prices!B16 -> -0.0079264343 | C17: =(Prices!D17 - Prices!D16) / Prices!D16 -> 0.0090913362 | D17: =(Prices!F17 - Prices!F16) / Prices!F16 -> -0.0003781104 | E17: =(Prices!G17 - Prices!G16) / Prices!G16 -> -0.013742237 | F17: =(Prices!H17 - Prices!H16) / Prices!H16 -> 0.00058409911 | G17: =(Prices!I17 - Prices!I16) / Prices!I16 -> -0.0047791623 | H17: =(Prices!J17 - Prices!J16) / Prices!J16 -> 0.057271267 | I17: =(Prices!K17 - Prices!K16) / Prices!K16 -> -0.0056934084 | J17: =(Prices!P17 - Prices!P16) / Prices!P16 -> 0.013630523 | K17: =(Prices!S17 - Prices!S16) / Prices!S16 -> 0.001402308 | L17: 0.0064755734 | M17: 0.0012833991 | N17: 0.00099156874
A18: 43490 | B18: =(Prices!B18 - Prices!B17) / Prices!B17 -> 0.033136846 | C18: =(Prices!D18 - Prices!D17) / Prices!D17 -> 0.0094506152 | D18: =(Prices!F18 - Prices!F17) / Prices!F17 -> 0.016153066 | E18: =(Prices!G18 - Prices!G17) / Prices!G17 -> 0.0094466535 | F18: =(Prices!H18 - Prices!H17) / Prices!H17 -> 0.0063269594 | G18: =(Prices!I18 - Prices!I17) / Prices!I17 -> 0.0091336342 | H18: =(Prices!J18 - Prices!J17) / Prices!J17 -> 0.014635027 | I18: =(Prices!K18 - Prices!K17) / Prices!K17 -> -0.0074232644 | J18: =(Prices!P18 - Prices!P17) / Prices!P17 -> 0.018970238 | K18: =(Prices!S18 - Prices!S17) / Prices!S17 -> 0.0044820487 | L18: 0.011948425 | M18: 0.012560753 | N18: 0.0085030793
A19: 43493 | B19: =(Prices!B19 - Prices!B18) / Prices!B18 -> -0.0092545668 | C19: =(Prices!D19 - Prices!D18) / Prices!D18 -> -0.019562217 | D19: =(Prices!F19 - Prices!F18) / Prices!F18 -> -0.019654848 | E19: =(Prices!G19 - Prices!G18) / Prices!G18 -> 0.0059268116 | F19: =(Prices!H19 - Prices!H18) / Prices!H18 -> 0.0047392998 | G19: =(Prices!I19 - Prices!I18) / Prices!I18 -> -0.019501687 | H19: =(Prices!J19 - Prices!J18) / Prices!J18 -> -0.13824547 | I19: =(Prices!K19 - Prices!K18) / Prices!K18 -> -0.00085487787 | J19: =(Prices!P19 - Prices!P18) / Prices!P18 -> -0.0022219545 | K19: =(Prices!S19 - Prices!S18) / Prices!S18 -> -0.006692927 | L19: -0.012352026 | M19: -0.0048101135 | N19: -0.0077356981
A20: 43494 | B20: =(Prices!B20 - Prices!B19) / Prices!B19 -> -0.010364564 | C20: =(Prices!D20 - Prices!D19) / Prices!D19 -> -0.026869942 | D20: =(Prices!F20 - Prices!F19) / Prices!F19 -> -0.0090752295 | E20: =(Prices!G20 - Prices!G19) / Prices!G19 -> 0.010388464 | F20: =(Prices!H20 - Prices!H19) / Prices!H19 -> 0.0027917299 | G20: =(Prices!I20 - Prices!I19) / Prices!I19 -> -0.020365406 | H20: =(Prices!J20 - Prices!J19) / Prices!J19 -> -0.046445776 | I20: =(Prices!K20 - Prices!K19) / Prices!K19 -> 0.00021395065 | J20: =(Prices!P20 - Prices!P19) / Prices!P19 -> 0.003643996 | K20: =(Prices!S20 - Prices!S19) / Prices!S19 -> 0.0037900366 | L20: -0.0094417295 | M20: 0.0027982308 | N20: -0.0012373474
A21: 43495 | B21: =(Prices!B21 - Prices!B20) / Prices!B20 -> 0.06833435 | C21: =(Prices!D21 - Prices!D20) / Prices!D20 -> 0.048027447 | D21: =(Prices!F21 - Prices!F20) / Prices!F20 -> 0.026101426 | E21: =(Prices!G21 - Prices!G20) / Prices!G20 -> 0.010051265 | F21: =(Prices!H21 - Prices!H20) / Prices!H20 -> 0.0023036847 | G21: =(Prices!I21 - Prices!I20) / Prices!I20 -> 0.033417555 | H21: =(Prices!J21 - Prices!J20) / Prices!J20 -> 0.043997092 | I21: =(Prices!K21 - Prices!K20) / Prices!K20 -> 0.010476702 | J21: =(Prices!P21 - Prices!P20) / Prices!P20 -> 0.038021903 | K21: =(Prices!S21 - Prices!S20) / Prices!S20 -> 0.010907818 | L21: 0.025437736 | M21: 0.011162171 | N21: 0.015817925
A22: 43496 | B22: =(Prices!B22 - Prices!B21) / Prices!B21 -> 0.0072014756 | C22: =(Prices!D22 - Prices!D21) / Prices!D21 -> 0.028914722 | D22: =(Prices!F22 - Prices!F21) / Prices!F21 -> 0.025409888 | E22: =(Prices!G22 - Prices!G21) / Prices!G21 -> 0.010939397 | F22: =(Prices!H22 - Prices!H21) / Prices!H21 -> -0.0087155369 | G22: =(Prices!I22 - Prices!I21) / Prices!I21 -> -0.018330716 | H22: =(Prices!J22 - Prices!J21) / Prices!J21 -> 0.04629152 | I22: =(Prices!K22 - Prices!K21) / Prices!K21 -> 0.0206306 | J22: =(Prices!P22 - Prices!P21) / Prices!P21 -> -0.0056676551 | K22: =(Prices!S22 - Prices!S21) / Prices!S21 -> 0.013694851 | L22: 0.014968979 | M22: 0.00025065838 | N22: 0.0083347817
A23: 43497 | B23: =(Prices!B23 - Prices!B22) / Prices!B22 -> 0.00048064454 | C23: =(Prices!D23 - Prices!D22) / Prices!D22 -> -0.053818808 | D23: =(Prices!F23 - Prices!F22) / Prices!F22 -> -0.0064570626 | E23: =(Prices!G23 - Prices!G22) / Prices!G22 -> 0.0084156829 | F23: =(Prices!H23 - Prices!H22) / Prices!H22 -> 0.0036715876 | G23: =(Prices!I23 - Prices!I22) / Prices!I22 -> -0.015799809 | H23: =(Prices!J23 - Prices!J22) / Prices!J22 -> 0.0068173588 | I23: =(Prices!K23 - Prices!K22) / Prices!K22 -> 0.010365817 | J23: =(Prices!P23 - Prices!P22) / Prices!P22 -> 0.016904375 | K23: =(Prices!S23 - Prices!S22) / Prices!S22 -> 0.036025869 | L23: -0.0042224573 | M23: -0.00050178524 | N23: 0.00084657316 | Q23: AAPL | R23: AMZN | S23: GOOGL | T23: JNJ | U23: JPM | V23: MSFT | W23: NVDA | X23: PG | Y23: TSLA | Z23: XOM | AA23: QQQ | AB23: VEA | AC23: VOO
A24: 43500 | B24: =(Prices!B24 - Prices!B23) / Prices!B23 -> 0.028404733 | C24: =(Prices!D24 - Prices!D23) / Prices!D23 -> 0.0043535819 | D24: =(Prices!F24 - Prices!F23) / Prices!F23 -> 0.020382388 | E24: =(Prices!G24 - Prices!G23) / Prices!G23 -> -0.0098360849 | F24: =(Prices!H24 - Prices!H23) / Prices!H23 -> 0.0035616208 | G24: =(Prices!I24 - Prices!I23) / Prices!I23 -> 0.028799311 | H24: =(Prices!J24 - Prices!J23) / Prices!J23 -> 0.030746969 | I24: =(Prices!K24 - Prices!K23) / Prices!K23 -> 0.0057457143 | J24: =(Prices!P24 - Prices!P23) / Prices!P23 -> 0.0021780467 | K24: =(Prices!S24 - Prices!S23) / Prices!S23 -> -0.014488789 | L24: 0.012421542 | M24: 0.0035128335 | N24: 0.0071308573 | P24: AAPL | Q24: =VARP(Stocks!$B$2:$B$1510) -> 0.0003773681 | R24: 0.00024661293 | S24: 0.00024385552 | T24: 8.4605352e-05 | U24: 0.00015484545 | V24: 0.00026061321 | W24: 0.00038305354 | X24: 9.9485102e-05 | Y24: 0.00036746945 | Z24: 0.00011476338 | AA24: 0.00024862973 | AB24: 0.00014406421 | AC24: 0.00019218852
A25: 43501 | B25: =(Prices!B25 - Prices!B24) / Prices!B24 -> 0.017109671 | C25: =(Prices!D25 - Prices!D24) / Prices!D24 -> 0.015612487 | D25: =(Prices!F25 - Prices!F24) / Prices!F24 -> 0.0091551213 | E25: =(Prices!G25 - Prices!G24) / Prices!G24 -> 0 | F25: =(Prices!H25 - Prices!H24) / Prices!H24 -> -0.0044124206 | G25: =(Prices!I25 - Prices!I24) / Prices!I24 -> 0.01399668 | H25: =(Prices!J25 - Prices!J24) / Prices!J24 -> 0.0051615757 | I25: =(Prices!K25 - Prices!K24) / Prices!K24 -> -0.0060188666 | J25: =(Prices!P25 - Prices!P24) / Prices!P24 -> 0.027038217 | K25: =(Prices!S25 - Prices!S24) / Prices!S24 -> 0.010291282 | L25: 0.0088481252 | M25: 0.0080023437 | N25: 0.0044402667 | P25: AMZN | Q25: 0.00024661293 | R25: =VARP(Stocks!$C$2:$C$1510) -> 0.00046217262 | S25: 0.00027236945 | T25: 4.8575544e-05 | U25: 0.0001148991 | V25: 0.00026776092 | W25: 0.00040605649 | X25: 6.3756519e-05 | Y25: 0.0003673467 | Z25: 6.3946751e-05 | AA25: 0.00025409919 | AB25: 0.00012927798 | AC25: 0.00017564649
A26: 43502 | B26: =(Prices!B26 - Prices!B25) / Prices!B25 -> 0.00034421134 | C26: =(Prices!D26 - Prices!D25) / Prices!D25 -> -0.01118269 | D26: =(Prices!F26 - Prices!F25) / Prices!F25 -> -0.02515908 | E26: =(Prices!G26 - Prices!G25) / Prices!G25 -> 0.00090302775 | F26: =(Prices!H26 - Prices!H25) / Prices!H25 -> -0.00048167676 | G26: =(Prices!I26 - Prices!I25) / Prices!I25 -> -0.011098815 | H26: =(Prices!J26 - Prices!J25) / Prices!J25 -> 0.020339931 | I26: =(Prices!K26 - Prices!K25) / Prices!K25 -> 0.0049262948 | J26: =(Prices!P26 - Prices!P25) / Prices!P25 -> -0.012851945 | K26: =(Prices!S26 - Prices!S25) / Prices!S25 -> -0.0043655216 | L26: -0.0029818639 | M26: -0.0064496552 | N26: -0.0012345895 | P26: GOOGL | Q26: 0.00024385552 | R26: 0.00027236945 | S26: =VARP(Stocks!$D$2:$D$1510) -> 0.00038634061 | T26: 6.8672453e-05 | U26: 0.00015316183 | V26: 0.00026440972 | W26: 0.000372751 | X26: 8.118512e-05 | Y26: 0.00030716518 | Z26: 0.00010750931 | AA26: 0.00023890954 | AB26: 0.00013989659 | AC26: 0.00018282988
A27: 43503 | B27: =(Prices!B27 - Prices!B26) / Prices!B26 -> -0.018939385 | C27: =(Prices!D27 - Prices!D26) / Prices!D26 -> -0.01578411 | D27: =(Prices!F27 - Prices!F26) / Prices!F26 -> -0.015121541 | E27: =(Prices!G27 - Prices!G26) / Prices!G26 -> -0.0071428457 | F27: =(Prices!H27 - Prices!H26) / Prices!H26 -> -0.013109449 | G27: =(Prices!I27 - Prices!I26) / Prices!I26 -> -0.0071678449 | H27: =(Prices!J27 - Prices!J26) / Prices!J26 -> -0.03647057 | I27: =(Prices!K27 - Prices!K26) / Prices!K26 -> -0.0079656286 | J27: =(Prices!P27 - Prices!P26) / Prices!P26 -> -0.030609662 | K27: =(Prices!S27 - Prices!S26) / Prices!S26 -> -0.0077069153 | L27: -0.013429581 | M27: -0.012734346 | N27: -0.0098091667 | P27: JNJ | Q27: 8.4605352e-05 | R27: 4.8575544e-05 | S27: 6.8672453e-05 | T27: =VARP(Stocks!$E$2:$E$1510) -> 0.00014549056 | U27: 9.116294e-05 | V27: 8.1909321e-05 | W27: 6.0578399e-05 | X27: 8.8098768e-05 | Y27: 3.8025565e-05 | Z27: 7.2092085e-05 | AA27: 6.8706936e-05 | AB27: 6.1228459e-05 | AC27: 7.8255818e-05
A28: 43504 | B28: =(Prices!B28 - Prices!B27) / Prices!B27 -> 0.0011750957 | C28: =(Prices!D28 - Prices!D27) / Prices!D27 -> -0.016198209 | D28: =(Prices!F28 - Prices!F27) / Prices!F27 -> -0.0031920492 | E28: =(Prices!G28 - Prices!G27) / Prices!G27 -> 0.0026503625 | F28: =(Prices!H28 - Prices!H27) / Prices!H27 -> -0.0099631865 | G28: =(Prices!I28 - Prices!I27) / Prices!I27 -> 0.0037996884 | H28: =(Prices!J28 - Prices!J27) / Prices!J27 -> 0.0050877084 | I28: =(Prices!K28 - Prices!K27) / Prices!K27 -> 0.0058675693 | J28: =(Prices!P28 - Prices!P27) / Prices!P27 -> -0.0055608102 | K28: =(Prices!S28 - Prices!S27) / Prices!S27 -> 0.0016248405 | L28: 0.0019615102 | M28: -0.0035403744 | N28: 0.0012886351 | P28: JPM | Q28: 0.00015484545 | R28: 0.0001148991 | S28: 0.00015316183 | T28: 9.116294e-05 | U28: =VARP(Stocks!$F$2:$F$1510) -> 0.00037283239 | V28: 0.00014948802 | W28: 0.00021220474 | X28: 8.5572349e-05 | Y28: 0.00021111105 | Z28: 0.00022231336 | AA28: 0.00015095619 | AB28: 0.00015858986 | AC28: 0.00017343451
A29: 43507 | B29: =(Prices!B29 - Prices!B28) / Prices!B28 -> -0.0057506202 | C29: =(Prices!D29 - Prices!D28) / Prices!D28 -> 0.0017503864 | D29: =(Prices!F29 - Prices!F28) / Prices!F28 -> -0.00023576156 | E29: =(Prices!G29 - Prices!G28) / Prices!G28 -> -0.0030211694 | F29: =(Prices!H29 - Prices!H28) / Prices!H28 -> -0.0047355544 | G29: =(Prices!I29 - Prices!I28) / Prices!I28 -> -0.0039745167 | H29: =(Prices!J29 - Prices!J28) / Prices!J28 -> -0.011608447 | I29: =(Prices!K29 - Prices!K28) / Prices!K28 -> 0.0057314162 | J29: =(Prices!P29 - Prices!P28) / Prices!P28 -> 0.023021598 | K29: =(Prices!S29 - Prices!S28) / Prices!S28 -> 0.0016222753 | L29: -0.00094908743 | M29: -0.0020306025 | N29: 0.00052282143 | P29: MSFT | Q29: 0.00026061321 | R29: 0.00026776092 | S29: 0.00026440972 | T29: 8.1909321e-05 | U29: 0.00014948802 | V29: =VARP(Stocks!$G$2:$G$1510) -> 0.0003336092 | W29: 0.00040054948 | X29: 0.00010305172 | Y29: 0.00032047869 | Z29: 9.3865446e-05 | AA29: 0.00024610208 | AB29: 0.00014130649 | AC29: 0.00018945775
A30: 43508 | B30: =(Prices!B30 - Prices!B29) / Prices!B29 -> 0.0086169237 | C30: =(Prices!D30 - Prices!D29) / Prices!D29 -> 0.029547383 | D30: =(Prices!F30 - Prices!F29) / Prices!F29 -> 0.023100945 | E30: =(Prices!G30 - Prices!G29) / Prices!G29 -> 0.016363851 | F30: =(Prices!H30 - Prices!H29) / Prices!H29 -> 0.017050061 | G30: =(Prices!I30 - Prices!I29) / Prices!I29 -> 0.015581961 | H30: =(Prices!J30 - Prices!J29) / Prices!J29 -> 0.032229491 | I30: =(Prices!K30 - Prices!K29) / Prices!K29 -> 0.010074234 | J30: =(Prices!P30 - Prices!P29) / Prices!P29 -> -0.0032924992 | K30: =(Prices!S30 - Prices!S29) / Prices!S29 -> 0.017543741 | L30: 0.014786465 | M30: 0.013224869 | N30: 0.012943033 | P30: NVDA | Q30: 0.00038305354 | R30: 0.00040605649 | S30: 0.000372751 | T30: 6.0578399e-05 | U30: 0.00021220474 | V30: 0.00040054948 | W30: =VARP(Stocks!$H$2:$H$1510) -> 0.0010679024 | X30: 9.4046519e-05 | Y30: 0.0006019799 | Z30: 0.00013393343 | AA30: 0.00039982143 | AB30: 0.00022299789 | AC30: 0.00028645461
A31: 43509 | B31: =(Prices!B31 - Prices!B30) / Prices!B30 -> -0.0041546768 | C31: =(Prices!D31 - Prices!D30) / Prices!D30 -> 0.0012149201 | D31: =(Prices!F31 - Prices!F30) / Prices!F30 -> 0.00093110542 | E31: =(Prices!G31 - Prices!G30) / Prices!G30 -> 0.0021614036 | F31: =(Prices!H31 - Prices!H30) / Prices!H30 -> 0.0047758813 | G31: =(Prices!I31 - Prices!I30) / Prices!I30 -> -0.00074843544 | H31: =(Prices!J31 - Prices!J30) / Prices!J30 -> 0.011311662 | I31: =(Prices!K31 - Prices!K30) / Prices!K30 -> -0.00020166935 | J31: =(Prices!P31 - Prices!P30) / Prices!P30 -> -0.011673756 | K31: =(Prices!S31 - Prices!S30) / Prices!S30 -> 0.011273273 | L31: 0.00070178352 | M31: 0.00025066531 | N31: 0.0030162582 | P31: PG | Q31: 9.9485102e-05 | R31: 6.3756519e-05 | S31: 8.118512e-05 | T31: 8.8098768e-05 | U31: 8.5572349e-05 | V31: 0.00010305172 | W31: 9.4046519e-05 | X31: =VARP(Stocks!$I$2:$I$1510) -> 0.00016283757 | Y31: 5.0168386e-05 | Z31: 5.6553956e-05 | AA31: 8.4430974e-05 | AB31: 6.7650603e-05 | AC31: 8.8157964e-05
A32: 43510 | B32: =(Prices!B32 - Prices!B31) / Prices!B31 -> 0.003643185 | C32: =(Prices!D32 - Prices!D31) / Prices!D31 -> -0.010579272 | D32: =(Prices!F32 - Prices!F31) / Prices!F31 -> 0.0005050999 | E32: =(Prices!G32 - Prices!G31) / Prices!G31 -> -0.001041 | F32: =(Prices!H32 - Prices!H31) / Prices!H31 -> -0.0064993126 | G32: =(Prices!I32 - Prices!I31) / Prices!I31 -> 0.00084259189 | H32: =(Prices!J32 - Prices!J31) / Prices!J31 -> 0.010792682 | I32: =(Prices!K32 - Prices!K31) / Prices!K31 -> -0.007859588 | J32: =(Prices!P32 - Prices!P31) / Prices!P31 -> -0.01427782 | K32: =(Prices!S32 - Prices!S31) / Prices!S31 -> 0.00026210151 | L32: 0.0012283321 | M32: 0 | N32: -0.0022159574 | P32: TSLA | Q32: 0.00036746945 | R32: 0.0003673467 | S32: 0.00030716518 | T32: 3.8025565e-05 | U32: 0.00021111105 | V32: 0.00032047869 | W32: 0.0006019799 | X32: 5.0168386e-05 | Y32: =VARP(Stocks!$J$2:$J$1510) -> 0.0016490219 | Z32: 0.00012326062 | AA32: 0.00035962376 | AB32: 0.00020464161 | AC32: 0.00024910467
A33: 43511 | B33: =(Prices!B33 - Prices!B32) / Prices!B32 -> -0.002224754 | C33: =(Prices!D33 - Prices!D32) / Prices!D32 -> -0.0090592625 | D33: =(Prices!F33 - Prices!F32) / Prices!F32 -> -0.008475077 | E33: =(Prices!G33 - Prices!G32) / Prices!G32 -> 0.015412068 | F33: =(Prices!H33 - Prices!H32) / Prices!H32 -> 0.030560488 | G33: =(Prices!I33 - Prices!I32) / Prices!I32 -> 0.012347992 | H33: =(Prices!J33 - Prices!J32) / Prices!J32 -> 0.0181844 | I33: =(Prices!K33 - Prices!K32) / Prices!K32 -> 0.00020321616 | J33: =(Prices!P33 - Prices!P32) / Prices!P32 -> 0.013529982 | K33: =(Prices!S33 - Prices!S32) / Prices!S32 -> 0.01888054 | L33: 0.0042050071 | M33: 0.013550723 | N33: 0.01102319 | P33: XOM | Q33: 0.00011476338 | R33: 6.3946751e-05 | S33: 0.00010750931 | T33: 7.2092085e-05 | U33: 0.00022231336 | V33: 9.3865446e-05 | W33: 0.00013393343 | X33: 5.6553956e-05 | Y33: 0.00012326062 | Z33: =VARP(Stocks!$K$2:$K$1510) -> 0.00041258679 | AA33: 0.00010346129 | AB33: 0.0001328279 | AC33: 0.00013496764
A34: 43515 | B34: =(Prices!B34 - Prices!B33) / Prices!B33 -> 0.002992487 | C34: =(Prices!D34 - Prices!D33) / Prices!D33 -> 0.012208075 | D34: =(Prices!F34 - Prices!F33) / Prices!F33 -> 0.0061448673 | E34: =(Prices!G34 - Prices!G33) / Prices!G33 -> -0.0050592896 | F34: =(Prices!H34 - Prices!H33) / Prices!H33 -> -0.0035054438 | G34: =(Prices!I34 - Prices!I33) / Prices!I33 -> -0.00046188207 | H34: =(Prices!J34 - Prices!J33) / Prices!J33 -> -0.0044491086 | I34: =(Prices!K34 - Prices!K33) / Prices!K33 -> 0.015333004 | J34: =(Prices!P34 - Prices!P33) / Prices!P33 -> -0.0072755921 | K34: =(Prices!S34 - Prices!S33) / Prices!S33 -> 0.0066915809 | L34: 0.0019773262 | M34: 0.0049519612 | N34: 0.0017257788 | P34: QQQ | Q34: 0.00024862973 | R34: 0.00025409919 | S34: 0.00023890954 | T34: 6.8706936e-05 | U34: 0.00015095619 | V34: 0.00024610208 | W34: 0.00039982143 | X34: 8.4430974e-05 | Y34: 0.00035962376 | Z34: 0.00010346129 | AA34: =VARP(Stocks!$L$2:$L$1510) -> 0.00023486806 | AB34: 0.00014088208 | AC34: 0.00018032821
A35: 43516 | B35: =(Prices!B35 - Prices!B34) / Prices!B34 -> 0.0064353816 | C35: =(Prices!D35 - Prices!D34) / Prices!D34 -> -0.0033668938 | D35: =(Prices!F35 - Prices!F34) / Prices!F34 -> -0.0052551867 | E35: =(Prices!G35 - Prices!G34) / Prices!G34 -> 0.0048640714 | F35: =(Prices!H35 - Prices!H34) / Prices!H34 -> 0.0048488915 | G35: =(Prices!I35 - Prices!I34) / Prices!I34 -> -0.0051992906 | H35: =(Prices!J35 - Prices!J34) / Prices!J34 -> 0.012193523 | I35: =(Prices!K35 - Prices!K34) / Prices!K34 -> -0.0071008029 | J35: =(Prices!P35 - Prices!P34) / Prices!P34 -> -0.01007714 | K35: =(Prices!S35 - Prices!S34) / Prices!S34 -> 0.0038348199 | L35: -0.00017398412 | M35: 0.0039417913 | N35: 0.0023097483 | P35: VEA | Q35: 0.00014406421 | R35: 0.00012927798 | S35: 0.00013989659 | T35: 6.1228459e-05 | U35: 0.00015858986 | V35: 0.00014130649 | W35: 0.00022299789 | X35: 6.7650603e-05 | Y35: 0.00020464161 | Z35: 0.0001328279 | AA35: 0.00014088208 | AB35: =VARP(Stocks!$M$2:$M$1510) -> 0.0001414285 | AC35: 0.000131837
A36: 43517 | B36: =(Prices!B36 - Prices!B35) / Prices!B35 -> -0.0056385055 | C36: =(Prices!D36 - Prices!D35) / Prices!D35 -> -0.0016398894 | D36: =(Prices!F36 - Prices!F35) / Prices!F35 -> -0.014617306 | E36: =(Prices!G36 - Prices!G35) / Prices!G35 -> -0.0068209032 | F36: =(Prices!H36 - Prices!H35) / Prices!H35 -> -0.0020815733 | G36: =(Prices!I36 - Prices!I35) / Prices!I35 -> 0.021092117 | H36: =(Prices!J36 - Prices!J35) / Prices!J35 -> -0.017533793 | I36: =(Prices!K36 - Prices!K35) / Prices!K35 -> 0.0050363492 | J36: =(Prices!P36 - Prices!P35) / Prices!P35 -> -0.037447192 | K36: =(Prices!S36 - Prices!S35) / Prices!S35 -> -0.0090411095 | L36: -0.0036573568 | M36: -0.0024540484 | N36: -0.0036328013 | P36: VOO | Q36: 0.00019218852 | R36: 0.00017564649 | S36: 0.00018282988 | T36: 7.8255818e-05 | U36: 0.00017343451 | V36: 0.00018945775 | W36: 0.00028645461 | X36: 8.8157964e-05 | Y36: 0.00024910467 | Z36: 0.00013496764 | AA36: 0.00018032821 | AB36: 0.000131837 | AC36: =VARP(Stocks!$N$2:$N$1510) -> 0.00016020973
A37: 43518 | B37: =(Prices!B37 - Prices!B36) / Prices!B36 -> 0.011165713 | C37: =(Prices!D37 - Prices!D36) / Prices!D36 -> 0.0074841032 | D37: =(Prices!F37 - Prices!F36) / Prices!F36 -> 0.011184466 | E37: =(Prices!G37 - Prices!G36) / Prices!G36 -> 0.0087135857 | F37: =(Prices!H37 - Prices!H36) / Prices!H36 -> -0.0044562856 | G37: =(Prices!I37 - Prices!I36) / Prices!I36 -> 0.01425815 | H37: =(Prices!J37 - Prices!J36) / Prices!J36 -> 0.021955242 | I37: =(Prices!K37 - Prices!K36) / Prices!K36 -> 0.0047103198 | J37: =(Prices!P37 - Prices!P36) / Prices!P36 -> 0.011949337 | K37: =(Prices!S37 - Prices!S36) / Prices!S36 -> 0.0077099807 | L37: 0.007399813 | M37: 0.00369007 | N37: 0.0059982163
A38: 43521 | B38: =(Prices!B38 - Prices!B37) / Prices!B37 -> 0.007284226 | C38: =(Prices!D38 - Prices!D37) / Prices!D37 -> 0.00088257365 | D38: =(Prices!F38 - Prices!F37) / Prices!F37 -> 0.00068976552 | E38: =(Prices!G38 - Prices!G37) / Prices!G37 -> 0.0036847392 | F38: =(Prices!H38 - Prices!H37) / Prices!H37 -> 0.010475911 | G38: =(Prices!I38 - Prices!I37) / Prices!I37 -> 0.0055871158 | H38: =(Prices!J38 - Prices!J37) / Prices!J37 -> -0.0031406241 | I38: =(Prices!K38 - Prices!K37) / Prices!K37 -> -0.0067830958 | J38: =(Prices!P38 - Prices!P37) / Prices!P37 -> 0.013776227 | K38: =(Prices!S38 - Prices!S37) / Prices!S37 -> 0.0010200612 | L38: 0.0036440952 | M38: 0.0031860398 | N38: 0.0014809026
A39: 43522 | B39: =(Prices!B39 - Prices!B38) / Prices!B38 -> 0.00057431248 | C39: =(Prices!D39 - Prices!D38) / Prices!D38 -> 0.0020820351 | D39: =(Prices!F39 - Prices!F38) / Prices!F38 -> 0.0041884399 | E39: =(Prices!G39 - Prices!G38) / Prices!G38 -> -0.00066101456 | F39: =(Prices!H39 - Prices!H38) / Prices!H38 -> -0.0076340734 | G39: =(Prices!I39 - Prices!I38) / Prices!I38 -> 0.0069003434 | H39: =(Prices!J39 - Prices!J38) / Prices!J38 -> -0.010019568 | I39: =(Prices!K39 - Prices!K38) / Prices!K38 -> 0.0026111796 | J39: =(Prices!P39 - Prices!P38) / Prices!P38 -> -0.00304584 | K39: =(Prices!S39 - Prices!S38) / Prices!S38 -> 0.0020385092 | L39: 0.0010373635 | M39: 0.0041536174 | N39: -0.00073922379
A40: 43523 | B40: =(Prices!B40 - Prices!B39) / Prices!B39 -> 0.0030976007 | C40: =(Prices!D40 - Prices!D39) / Prices!D39 -> 0.0028660116 | D40: =(Prices!F40 - Prices!F39) / Prices!F39 -> 0.00078424924 | E40: =(Prices!G40 - Prices!G39) / Prices!G39 -> -0.0017634421 | F40: =(Prices!H40 - Prices!H39) / Prices!H39 -> -0.0012346578 | G40: =(Prices!I40 - Prices!I39) / Prices!I39 -> -0.0016910971 | H40: =(Prices!J40 - Prices!J39) / Prices!J39 -> -0.010757481 | I40: =(Prices!K40 - Prices!K39) / Prices!K39 -> -0.0092154952 | J40: =(Prices!P40 - Prices!P39) / Prices!P39 -> 0.056671041 | K40: =(Prices!S40 - Prices!S39) / Prices!S39 -> 0.010297385 | L40: -0.00063343017 | M40: -0.0031628995 | N40: -0.00050616236
...

Sheet Bond ETF
A1: Date | B1: AGG | C1: BND | D1: SCHP | E1: SPTL | F1: TLT | J1: AGG | K1: BND | L1: SCHP | M1: SPTL | N1: TLT | P1: Total
A2: 43467 | I2: AVERAGE | J2: =AVERAGE(B3:B1510) -> 5.0822738e-05 | K2: =AVERAGE(C3:C1510) -> 5.363622e-05 | L2: =AVERAGE(D3:D1510) -> 0.00012105602 | M2: =AVERAGE(E3:E1510) -> -4.0415469e-05 | N2: =AVERAGE(F3:F1510) -> -6.080118e-05 | P2: =AVERAGE(J2:N2) -> 2.4859665e-05
A3: 43468 | B3: =(Prices!C3 - Prices!C2) / Prices!C2 -> 0.0041284596 | C3: =(Prices!E3 - Prices!E2) / Prices!E2 -> 0.0039066018 | D3: =(Prices!M3 - Prices!M2) / Prices!M2 -> 0.0061854267 | E3: =(Prices!N3 - Prices!N2) / Prices!N2 -> 0.011942217 | F3: =(Prices!O3 - Prices!O2) / Prices!O2 -> 0.011379466 | I3: STD. DEV. | J3: =_xlfn.STDEV.P(B3:B1510) -> 0.0040157153 | K3: =_xlfn.STDEV.P(C3:C1510) -> 0.0041250346 | L3: =_xlfn.STDEV.P(D3:D1510) -> 0.0041305485 | M3: =_xlfn.STDEV.P(E3:E1510) -> 0.010068961 | N3: =_xlfn.STDEV.P(F3:F1510) -> 0.010779048 | P3: =AVERAGE(J3:N3) -> 0.0066238614
A4: 43469 | B4: =(Prices!C4 - Prices!C3) / Prices!C3 -> -0.0029907793 | C4: =(Prices!E4 - Prices!E3) / Prices!E3 -> -0.0030127381 | D4: =(Prices!M4 - Prices!M3) / Prices!M3 -> -0.0026077914 | E4: =(Prices!N4 - Prices!N3) / Prices!N3 -> -0.01208186 | F4: =(Prices!O4 - Prices!O3) / Prices!O3 -> -0.011575352 | I4: VARIANCE | J4: =VAR(B3:B1510) -> 1.613667e-05 | K4: =VAR(C3:C1510) -> 1.7027202e-05 | L4: =VAR(D3:D1510) -> 1.7072752e-05 | M4: =VAR(E3:E1510) -> 0.00010145124 | N4: =VAR(F3:F1510) -> 0.00011626498 | P4: =AVERAGE(J4:N4) -> 5.3590568e-05
A5: 43472 | B5: =(Prices!C5 - Prices!C4) / Prices!C4 -> -0.0016869733 | C5: =(Prices!E5 - Prices!E4) / Prices!E4 -> -0.0015102734 | D5: =(Prices!M5 - Prices!M4) / Prices!M4 -> -0.00018679674 | E5: =(Prices!N5 - Prices!N4) / Prices!N4 -> -0.0022754262 | F5: =(Prices!O5 - Prices!O4) / Prices!O4 -> -0.0029479155 | I5: ANNUAL Returns | J5: =J2 * 252 -> 0.01280733 | K5: =K2 * 252 -> 0.013516327 | L5: =L2 * 252 -> 0.030506116 | M5: =M2 * 252 -> -0.010184698 | N5: =N2 * 252 -> -0.015321897 | P5: =AVERAGE(J5:N5) -> 0.0062646357
A6: 43473 | B6: =(Prices!C6 - Prices!C5) / Prices!C5 -> -0.000750965 | C6: =(Prices!E6 - Prices!E5) / Prices!E5 -> -0.0012606417 | D6: =(Prices!M6 - Prices!M5) / Prices!M5 -> 0.00056049491 | E6: =(Prices!N6 - Prices!N5) / Prices!N5 -> -0.0022807477 | F6: =(Prices!O6 - Prices!O5) / Prices!O5 -> -0.0026284044 | I6: Annual Volatility | J6: =J3 * SQRT(252) -> 0.063747504 | K6: =K3 * SQRT(252) -> 0.065482895 | L6: =L3 * SQRT(252) -> 0.065570424 | M6: =M3 * SQRT(252) -> 0.15983979 | N6: =N3 * SQRT(252) -> 0.17111208 | P6: =AVERAGE(J6:N6) -> 0.10515054
A7: 43474 | B7: =(Prices!C7 - Prices!C6) / Prices!C6 -> 0.0008457653 | C7: =(Prices!E7 - Prices!E6) / Prices!E6 -> 0.001388468 | D7: =(Prices!M7 - Prices!M6) / Prices!M6 -> 0.0013068167 | E7: =(Prices!N7 - Prices!N6) / Prices!N6 -> -0.0025714665 | F7: =(Prices!O7 - Prices!O6) / Prices!O6 -> -0.0015647898 | I7: Weights | J7: 0 | K7: 0 | L7: 1 | M7: 0 | N7: 0 | P7: =SUM(J7:N7) -> 1
A8: 43475 | B8: =(Prices!C8 - Prices!C7) / Prices!C7 -> -0.0011268214 | C8: =(Prices!E8 - Prices!E7) / Prices!E7 -> -0.0020169612 | D8: =(Prices!M8 - Prices!M7) / Prices!M7 -> -0.0022374369 | E8: =(Prices!N8 - Prices!N7) / Prices!N7 -> -0.0060154467 | F8: =(Prices!O8 - Prices!O7) / Prices!O7 -> -0.0064337729
A9: 43476 | B9: =(Prices!C9 - Prices!C8) / Prices!C8 -> 0.0014102686 | C9: =(Prices!E9 - Prices!E8) / Prices!E8 -> 0.0020210375 | D9: =(Prices!M9 - Prices!M8) / Prices!M8 -> 0.0028027953 | E9: =(Prices!N9 - Prices!N8) / Prices!N8 -> 0.0034586206 | F9: =(Prices!O9 - Prices!O8) / Prices!O8 -> 0.0039019708 | I9: Portfolio Return | J9: =SUMPRODUCT(J5:N5,J7:N7) -> 0.030506116 | L9: =SUMPRODUCT(L7, L5) -> 0.030506116 | N9: =SUMPRODUCT(N5:R5,N7:R7) -> 0.0062646357
A10: 43479 | B10: =(Prices!C10 - Prices!C9) / Prices!C9 -> -0.0014082825 | C10: =(Prices!E10 - Prices!E9) / Prices!E9 -> -0.0008824205 | D10: =(Prices!M10 - Prices!M9) / Prices!M9 -> -0.0020495359 | E10: =(Prices!N10 - Prices!N9) / Prices!N9 -> -0.0034466998 | F10: =(Prices!O10 - Prices!O9) / Prices!O9 -> -0.0037213483 | I10: Portfolio Annual Variance | J10: {=MMULT(MMULT(J7:N7, J16:N20), TRANSPOSE(J7:N7)) * 252} -> 0.0042994805 | N10: =SQRT(N9) -> 0.079149451
